Workbook
Name AA: #REF!
Name ADAD: #REF!
Name AEEA: #REF!
Name BB: #REF!
Name CC: #REF!
Name ĐÂ: #REF!
Name DD: #REF!
Name DE: #REF!
Name ds_hm: OFFSET('[1]BANG THEO DOI CHINH XAC'!$B:$B,0,0,COUNTA('[1]BANG THEO DOI CHINH XAC'!$B:$B)-1,1)
Name ds_hmtm: OFFSET('[1]BANG THEO DOI CHINH XAC'!$B:$B,MATCH('[1]BANG THEO DOI CHINH XAC'!A1:G2&"*",ds_hm,0)-1,0,COUNTIF(ds_hm,'[1]BANG THEO DOI CHINH XAC'!A1:G2&"*"),1)
Name Ể: #REF!
Name ÊRWRWRWRWR: #REF!
Name FSF: #REF!
Name FSFSF: #REF!
Name GDGD: #REF!
Name M: #REF!
Name MEAT_LONG_AN___NHÀ_XE_3_TẦNG: OFFSET([1]!Table1[TÊN HẠNG MỤC],MATCH('[1]BANG THEO DOI CHINH XAC'!A1&"*",TTT,0)-1,COUNTIF(TTT,'[1]BANG THEO DOI CHINH XAC'!A1&"*"),1)
Name mnr2c33: #REF!
Name mnr8c33: #REF!
Name ProjectList: [2]!Các_dự_án[DỰ ÁN]
Name ProjectStart: [3]!Nhiệm_vụ[[#Headers],[Dự án]]
Name RƯER: #REF!
Name SFSF: #REF!
Name TYPE: #REF!
Name YN_TYPE: #REF!

Sheet BIÊN BẢN BÀN GIAO
B5: BIÊN BẢN NGHIỆM THU VÀ BÀN GIAO SẢN PHẨM PROTOCOL OF PRODUCT ACCEPTANCE AND HANDOVER
C6: □ CK hoàn thiện/ Finished CK | G6: □ CK chưa hoàn thiện/Unfinished CK | K6: □ Chi tiết/phôi/ Detail/workpiece
J7: =[4]DATA!A3 -> 21.012-1 | S7: =VALUE(LEFT(K7,FIND(".",K7)-1)) -> #VALUE!
B8: CÔNG TRÌNH/ PROJECT : 10725-009 DGRP VIOLA - STRUCTURAL STEEL | K8: Ngày ban hành: 12/9/2025 [ Xưởng sản xuất]
B9: HẠNG MỤC : MAIN STRUCTURE + ERECTION RIG BEAM DETAIL | V9: =25+418+1021+187.5+100 -> 1751.5
B10: Địa điểm gia công/Production Location:AN HẠ - AH4 | K10: Ngày Bàn Giao: | V10: =25+556+731+731+798+411+100 -> 3352 | W10: =25+158+100 -> 283
B12: STT | C12: Tên - Mã số/ Name - Code | G12: Quy Cách/ Specification | H12: Chiều dài/ Length | I12: ĐVT/ Unit | J12: Số lượng/ Quantity | K12: Khối Lượng/ Weight [Kg] | L12: T.Khối lượng/ Total Weight [Kg] | M12: Diện Tích/ paint Area [M2] | N12: T.Diện Tích/ Total Area [M2] | O12: Barcode | P12: Rev | S12: Ghi Chú/ Remark
B14: A | J14: =SUBTOTAL(9,J15:J694) -> 46 | L14: =SUBTOTAL(9,L15:L694) -> 7539.58 | N14: =SUBTOTAL(9,N15:N694) -> 0
A15: =IF(B15="","","PRINT") -> PRINT | B15: =IF(C15="","",ROW()-14) -> 1 | C15: 1-01ERC3001-001 | D15: =MID(C15,3,13) -> 01ERC3001-001 | E15: =MID(D15,3,7) -> ERC3001 | F15: ERECTION RIG COLUMN | G15: H200*100*5.5*8 | H15: 3650 | I15: PCS | J15: 1 | K15: 117.43 | L15: 117.43 | M15: 2512101001A000220 | O15: 2602801007A000081 | P15: Rev.0 | Q15: F | R15: Dim,Visual
A16: =IF(B16="","","PRINT") -> PRINT | B16: =IF(C16="","",ROW()-14) -> 2 | C16: 1-01ERC3001-004 | D16: =MID(C16,3,13) -> 01ERC3001-004 | E16: =MID(D16,3,7) -> ERC3001 | F16: ERECTION RIG COLUMN | G16: H200*100*5.5*8 | H16: 3650 | I16: PCS | J16: 1 | K16: 117.43 | L16: 117.43 | O16: 2602801007A000080 | P16: Rev.0 | Q16: F | R16: Dim,Visual
A17: =IF(B17="","","PRINT") -> PRINT | B17: =IF(C17="","",ROW()-14) -> 3 | C17: 1-01ERC3001-003 | D17: =MID(C17,3,13) -> 01ERC3001-003 | E17: =MID(D17,3,7) -> ERC3001 | F17: ERECTION RIG COLUMN | G17: H200*100*5.5*8 | H17: 3650 | I17: PCS | J17: 1 | K17: 117.43 | L17: 117.43 | O17: 2602801007A000046 | P17: Rev.0 | Q17: F | R17: Dim,Visual
A18: =IF(B18="","","PRINT") -> PRINT | B18: =IF(C18="","",ROW()-14) -> 4 | C18: 1-01ERC3001-002 | D18: =MID(C18,3,13) -> 01ERC3001-002 | E18: =MID(D18,3,7) -> ERC3001 | F18: ERECTION RIG COLUMN | G18: H200*100*5.5*8 | H18: 3650 | I18: PCS | J18: 1 | K18: 117.43 | L18: 117.43 | O18: 2602801007A000043 | P18: Rev.0 | Q18: F | R18: Dim,Visual
A19: =IF(B19="","","PRINT") -> PRINT | B19: =IF(C19="","",ROW()-14) -> 5 | C19: 1-01ERC3002-002 | D19: =MID(C19,3,13) -> 01ERC3002-002 | E19: =MID(D19,3,7) -> ERC3002 | F19: ERECTION RIG COLUMN | G19: H200*100*5.5*8 | H19: 3650 | I19: PCS | J19: 1 | K19: 117.7 | L19: 117.7 | O19: 2602801007A000047 | P19: Rev.0 | Q19: F | R19: Dim,Visual
A20: =IF(B20="","","PRINT") -> PRINT | B20: =IF(C20="","",ROW()-14) -> 6 | C20: 1-01ERC3002-001 | D20: =MID(C20,3,13) -> 01ERC3002-001 | E20: =MID(D20,3,7) -> ERC3002 | F20: ERECTION RIG COLUMN | G20: H200*100*5.5*8 | H20: 3650 | I20: PCS | J20: 1 | K20: 117.7 | L20: 117.7 | O20: 2602801007A000044 | P20: Rev.0 | Q20: F | R20: Dim,Visual
A21: =IF(B21="","","PRINT") -> PRINT | B21: =IF(C21="","",ROW()-14) -> 7 | C21: 1-01ERC3012-008 | D21: =MID(C21,3,13) -> 01ERC3012-008 | E21: =MID(D21,3,7) -> ERC3012 | F21: ERECTION COLUMN | G21: H200*100*5.5*8 | H21: 750 | I21: PCS | J21: 1 | K21: 56.47 | L21: 56.47 | O21: 2602801007A000104 | P21: Rev.0 | Q21: F | R21: Dim,Visual
A22: =IF(B22="","","PRINT") -> PRINT | B22: =IF(C22="","",ROW()-14) -> 8 | C22: 1-01ERC3012-001 | D22: =MID(C22,3,13) -> 01ERC3012-001 | E22: =MID(D22,3,7) -> ERC3012 | F22: ERECTION COLUMN | G22: H200*100*5.5*8 | H22: 750 | I22: PCS | J22: 1 | K22: 56.47 | L22: 56.47 | O22: 2602801007A000109 | P22: Rev.0 | Q22: F | R22: Dim,Visual
A23: =IF(B23="","","PRINT") -> PRINT | B23: =IF(C23="","",ROW()-14) -> 9 | C23: 1-01ERC3012-012 | D23: =MID(C23,3,13) -> 01ERC3012-012 | E23: =MID(D23,3,7) -> ERC3012 | F23: ERECTION COLUMN | G23: H200*100*5.5*8 | H23: 750 | I23: PCS | J23: 1 | K23: 56.47 | L23: 56.47 | O23: 2602801007A000105 | P23: Rev.0 | Q23: F | R23: Dim,Visual
A24: =IF(B24="","","PRINT") -> PRINT | B24: =IF(C24="","",ROW()-14) -> 10 | C24: 1-01ERC3012-002 | D24: =MID(C24,3,13) -> 01ERC3012-002 | E24: =MID(D24,3,7) -> ERC3012 | F24: ERECTION COLUMN | G24: H200*100*5.5*8 | H24: 750 | I24: PCS | J24: 1 | K24: 56.47 | L24: 56.47 | O24: 2602801007A000110 | P24: Rev.0 | Q24: F | R24: Dim,Visual
A25: =IF(B25="","","PRINT") -> PRINT | B25: =IF(C25="","",ROW()-14) -> 11 | C25: 1-01ERC3012-004 | D25: =MID(C25,3,13) -> 01ERC3012-004 | E25: =MID(D25,3,7) -> ERC3012 | F25: ERECTION COLUMN | G25: H200*100*5.5*8 | H25: 750 | I25: PCS | J25: 1 | K25: 56.47 | L25: 56.47 | O25: 2602801007A000002 | P25: Rev.0 | Q25: F | R25: Dim,Visual
A26: =IF(B26="","","PRINT") -> PRINT | B26: =IF(C26="","",ROW()-14) -> 12 | C26: 1-01ERC3012-010 | D26: =MID(C26,3,13) -> 01ERC3012-010 | E26: =MID(D26,3,7) -> ERC3012 | F26: ERECTION COLUMN | G26: H200*100*5.5*8 | H26: 750 | I26: PCS | J26: 1 | K26: 56.47 | L26: 56.47 | O26: 2602801007A000108 | P26: Rev.0 | Q26: F | R26: Dim,Visual
A27: =IF(B27="","","PRINT") -> PRINT | B27: =IF(C27="","",ROW()-14) -> 13 | C27: 1-01ERC3012-009 | D27: =MID(C27,3,13) -> 01ERC3012-009 | E27: =MID(D27,3,7) -> ERC3012 | F27: ERECTION COLUMN | G27: H200*100*5.5*8 | H27: 750 | I27: PCS | J27: 1 | K27: 56.47 | L27: 56.47 | O27: 2602801007A000103 | P27: Rev.0 | Q27: F | R27: Dim,Visual
... A56: =IF(B56="","","PRINT") -> PRINT | B56: =IF(C56="","",ROW()-14) -> 42 | C56: 1-01ERC3010-002 | D56: =MID(C56,3,13) -> 01ERC3010-002 | E56: =MID(D56,3,7) -> ERC3010 | F56: ERECTION RIG COLUMN | G56: H200*100*5.5*8 | H56: 1890 | I56: PCS | J56: 1 | K56: 80.85 | L56: 80.85 | O56: 2602801007A000067 | P56: Rev.0 | Q56: F | R56: Dim,Visual
A57: =IF(B57="","","PRINT") -> PRINT | B57: =IF(C57="","",ROW()-14) -> 43 | C57: 1-01PEB3014-001 | D57: =MID(C57,3,13) -> 01PEB3014-001 | E57: =MID(D57,3,7) -> PEB3014 | F57: PLENUM EDGE BEAM | G57: [250*90*9*13 | H57: 5363 | I57: =IF(E57="", "", "PCS") -> PCS | J57: =IF(E57="","",RANDBETWEEN(1,1)) -> 1 | K57: 713.64 | L57: =IFERROR(K57*J57,"-") -> 713.64 | O57: 2602801001A002715 | P57: Rev.2 | Q57: F | R57: Dim,Visual
A58: =IF(B58="","","PRINT") -> PRINT | B58: =IF(C58="","",ROW()-14) -> 44 | C58: 2-03USG3003-001 | D58: =MID(C58,3,13) -> 03USG3003-001 | E58: =MID(D58,3,7) -> USG3003 | F58: UNDER GIRDER | G58: HSS355.5X9.53 | H58: 10785 | I58: =IF(E58="", "", "PCS") -> PCS | J58: =IF(E58="","",RANDBETWEEN(1,1)) -> 1 | K58: 1153.78 | L58: =IFERROR(K58*J58,"-") -> 1153.78 | O58: 2602801001A008429 | P58: Rev.0 | Q58: F | R58: Dim,Visual
A59: =IF(B59="","","PRINT") -> PRINT | B59: =IF(C59="","",ROW()-14) -> 45 | C59: 4-02USG3008-001 | D59: =MID(C59,3,13) -> 02USG3008-001 | E59: =MID(D59,3,7) -> USG3008 | F59: UNDER GIRDER | G59: HSS355.5X9.53 | H59: 11800 | I59: =IF(E59="", "", "PCS") -> PCS | J59: =IF(E59="","",RANDBETWEEN(1,1)) -> 1 | K59: 992.31 | L59: =IFERROR(K59*J59,"-") -> 992.31 | P59: Rev.0 | Q59: F | R59: Dim,Visual
A60: =IF(B60="","","PRINT") -> PRINT | B60: =IF(C60="","",ROW()-14) -> 46 | C60: 4-06USG3006-001 | D60: =MID(C60,3,13) -> 06USG3006-001 | E60: =MID(D60,3,7) -> USG3006 | F60: UNDER GIRDER | G60: HSS355.5X9.53 | H60: 11824 | I60: =IF(E60="", "", "PCS") -> PCS | J60: =IF(E60="","",RANDBETWEEN(1,1)) -> 1 | K60: 994.09 | L60: =IFERROR(K60*J60,"-") -> 994.09 | P60: Rev.0 | Q60: F | R60: Dim,Visual
A61: =IF(B61="","","PRINT") | B61: =IF(C61="","",ROW()-14) | D61: =MID(C61,3,13) | E61: =MID(D61,3,7) | F61: FAN DECK BEAM | G61: H200*100*5.5*8 | H61: 778 | I61: PCS | J61: 1 | K61: 16.56 | L61: 16.56 | O61: 2512101001A030867 | P61: Rev.0 | R61: Dim
A62: =IF(B62="","","PRINT") | B62: =IF(C62="","",ROW()-14) | D62: =MID(C62,3,13) | E62: =MID(D62,3,7) | F62: FAN DECK BEAM | G62: H200*100*5.5*8 | H62: 778 | I62: PCS | J62: 1 | K62: 16.56 | L62: 16.56 | O62: 2512101001A040614 | P62: Rev.0 | R62: Dim
A63: =IF(B63="","","PRINT") | B63: =IF(C63="","",ROW()-14) | D63: =MID(C63,3,13) | E63: =MID(D63,3,7) | F63: FAN DECK BEAM | G63: H200*100*5.5*8 | H63: 778 | I63: PCS | J63: 1 | K63: 16.56 | L63: 16.56 | O63: 2512101001A040352 | P63: Rev.0 | R63: Dim
A64: =IF(B64="","","PRINT") | B64: =IF(C64="","",ROW()-14) | D64: =MID(C64,3,13) | E64: =MID(D64,3,7) | F64: FAN DECK BEAM | G64: H200*100*5.5*8 | H64: 778 | I64: PCS | J64: 1 | K64: 16.56 | L64: 16.56 | O64: 2512101001A040184 | P64: Rev.0 | R64: Dim
A65: =IF(B65="","","PRINT") | B65: =IF(C65="","",ROW()-14) | D65: =MID(C65,3,13) | E65: =MID(D65,3,7) | F65: FAN DECK BEAM | G65: H200*100*5.5*8 | H65: 198 | I65: PCS | J65: 1 | K65: 4.21 | L65: 4.21 | O65: 2512101001A032614 | P65: Rev.0 | R65: Dim
A66: =IF(B66="","","PRINT") | B66: =IF(C66="","",ROW()-14) | D66: =MID(C66,3,13) | E66: =MID(D66,3,7) | F66: FAN DECK BEAM | G66: H200*100*5.5*8 | H66: 198 | I66: PCS | J66: 1 | K66: 4.21 | L66: 4.21 | O66: 2512101001A041918 | P66: Rev.0 | R66: Dim
A67: =IF(B67="","","PRINT") | B67: =IF(C67="","",ROW()-14) | D67: =MID(C67,3,13) | E67: =MID(D67,3,7) | F67: FAN DECK BEAM | G67: H200*100*5.5*8 | H67: 198 | I67: PCS | J67: 1 | K67: 4.21 | L67: 4.21 | O67: 2512101001A033838 | P67: Rev.0 | R67: Dim
A68: =IF(B68="","","PRINT") | B68: =IF(C68="","",ROW()-14) | D68: =MID(C68,3,13) | E68: =MID(D68,3,7) | F68: FAN DECK BEAM | G68: H200*100*5.5*8 | H68: 198 | I68: PCS | J68: 1 | K68: 4.21 | L68: 4.21 | O68: 2512101001A033551 | P68: Rev.0 | R68: Dim
A69: =IF(B69="","","PRINT") | B69: =IF(C69="","",ROW()-14) | D69: =MID(C69,3,13) | E69: =MID(D69,3,7) | F69: FAN DECK BEAM | G69: H200*100*5.5*8 | H69: 198 | I69: PCS | J69: 1 | K69: 4.21 | L69: 4.21 | O69: 2512101001A031658 | P69: Rev.0 | R69: Dim
A70: =IF(B70="","","PRINT") | B70: =IF(C70="","",ROW()-14) | D70: =MID(C70,3,13) | E70: =MID(D70,3,7) | F70: FAN DECK BEAM | G70: H200*100*5.5*8 | H70: 198 | I70: PCS | J70: 1 | K70: 4.21 | L70: 4.21 | O70: 2512101001A041501 | P70: Rev.0 | R70: Dim
A71: =IF(B71="","","PRINT") | B71: =IF(C71="","",ROW()-14) | D71: =MID(C71,3,13) | E71: =MID(D71,3,7) | F71: FAN DECK BEAM | G71: H200*100*5.5*8 | H71: 198 | I71: PCS | J71: 1 | K71: 4.21 | L71: 4.21 | O71: 2512101001A034453 | P71: Rev.0 | R71: Dim
A72: =IF(B72="","","PRINT") | B72: =IF(C72="","",ROW()-14) | D72: =MID(C72,3,13) | E72: =MID(D72,3,7) | F72: FAN DECK BEAM | G72: H200*100*5.5*8 | H72: 198 | I72: PCS | J72: 1 | K72: 4.21 | L72: 4.21 | O72: 2512101001A031785 | P72: Rev.0 | R72: Dim
A73: =IF(B73="","","PRINT") | B73: =IF(C73="","",ROW()-14) | D73: =MID(C73,3,13) | E73: =MID(D73,3,7) | F73: FAN DECK BEAM | G73: H200*100*5.5*8 | H73: 1122 | I73: =IF(E73="", "", "PCS") | J73: =IF(E73="","",RANDBETWEEN(1,1)) | K73: 27.75 | L73: =IFERROR(K73*J73,"-") -> - | O73: 2512101001A036105 | P73: Rev.0 | Q73: F | R73: Dim,Visual
A74: =IF(B74="","","PRINT") | B74: =IF(C74="","",ROW()-14) | D74: =MID(C74,3,13) | E74: =MID(D74,3,7) | F74: FAN DECK BEAM | G74: H200*100*5.5*8 | H74: 1122 | I74: =IF(E74="", "", "PCS") | J74: =IF(E74="","",RANDBETWEEN(1,1)) | K74: 27.75 | L74: =IFERROR(K74*J74,"-") -> - | O74: 2512101001A039061 | P74: Rev.0 | Q74: F | R74: Dim,Visual
...

Sheet Sheet3
D3: ='BIÊN BẢN BÀN GIAO'!#REF! -> #REF! | E3: ='BIÊN BẢN BÀN GIAO'!#REF! -> #REF!
D4: ='BIÊN BẢN BÀN GIAO'!#REF! -> #REF! | E4: ='BIÊN BẢN BÀN GIAO'!#REF! -> #REF!
D5: ='BIÊN BẢN BÀN GIAO'!#REF! -> #REF! | E5: ='BIÊN BẢN BÀN GIAO'!#REF! -> #REF! | F5: 2 | G5: ='BIÊN BẢN BÀN GIAO'!#REF! -> #REF! | H5: ='BIÊN BẢN BÀN GIAO'!#REF! -> #REF!
D6: ='BIÊN BẢN BÀN GIAO'!#REF! -> #REF! | E6: ='BIÊN BẢN BÀN GIAO'!#REF! -> #REF!
D7: ='BIÊN BẢN BÀN GIAO'!#REF! -> #REF! | E7: ='BIÊN BẢN BÀN GIAO'!#REF! -> #REF! | F7: 2 | G7: ='BIÊN BẢN BÀN GIAO'!#REF! -> #REF! | H7: ='BIÊN BẢN BÀN GIAO'!#REF! -> #REF!
D8: ='BIÊN BẢN BÀN GIAO'!#REF! -> #REF! | E8: ='BIÊN BẢN BÀN GIAO'!#REF! -> #REF!
D9: ='BIÊN BẢN BÀN GIAO'!#REF! -> #REF! | E9: ='BIÊN BẢN BÀN GIAO'!#REF! -> #REF! | F9: 2 | G9: ='BIÊN BẢN BÀN GIAO'!#REF! -> #REF! | H9: ='BIÊN BẢN BÀN GIAO'!#REF! -> #REF!
D10: ='BIÊN BẢN BÀN GIAO'!#REF! -> #REF! | E10: ='BIÊN BẢN BÀN GIAO'!#REF! -> #REF! | F10: 2 | G10: ='BIÊN BẢN BÀN GIAO'!#REF! -> #REF! | H10: ='BIÊN BẢN BÀN GIAO'!#REF! -> #REF!
D11: ='BIÊN BẢN BÀN GIAO'!#REF! -> #REF! | E11: ='BIÊN BẢN BÀN GIAO'!#REF! -> #REF!
D12: ='BIÊN BẢN BÀN GIAO'!#REF! -> #REF! | E12: ='BIÊN BẢN BÀN GIAO'!#REF! -> #REF!
D13: ='BIÊN BẢN BÀN GIAO'!#REF! -> #REF! | E13: ='BIÊN BẢN BÀN GIAO'!#REF! -> #REF!
D14: ='BIÊN BẢN BÀN GIAO'!#REF! -> #REF! | E14: ='BIÊN BẢN BÀN GIAO'!#REF! -> #REF!
D15: ='BIÊN BẢN BÀN GIAO'!#REF! -> #REF! | E15: ='BIÊN BẢN BÀN GIAO'!#REF! -> #REF!
D16: ='BIÊN BẢN BÀN GIAO'!#REF! -> #REF! | E16: ='BIÊN BẢN BÀN GIAO'!#REF! -> #REF!
D17: ='BIÊN BẢN BÀN GIAO'!#REF! -> #REF! | E17: ='BIÊN BẢN BÀN GIAO'!#REF! -> #REF! | F17: 4
D18: ='BIÊN BẢN BÀN GIAO'!#REF! -> #REF! | E18: ='BIÊN BẢN BÀN GIAO'!#REF! -> #REF!
D19: ='BIÊN BẢN BÀN GIAO'!#REF! -> #REF! | E19: ='BIÊN BẢN BÀN GIAO'!#REF! -> #REF!
D20: ='BIÊN BẢN BÀN GIAO'!#REF! -> #REF! | E20: ='BIÊN BẢN BÀN GIAO'!#REF! -> #REF! | M20: FBB7003 | N20: 5
D21: ='BIÊN BẢN BÀN GIAO'!#REF! -> #REF! | E21: ='BIÊN BẢN BÀN GIAO'!#REF! -> #REF! | M21: FBB7010 | N21: 9
D22: ='BIÊN BẢN BÀN GIAO'!#REF! -> #REF! | E22: ='BIÊN BẢN BÀN GIAO'!#REF! -> #REF! | M22: FBB7004 | N22: 3
D23: ='BIÊN BẢN BÀN GIAO'!#REF! -> #REF! | E23: ='BIÊN BẢN BÀN GIAO'!#REF! -> #REF!
D24: ='BIÊN BẢN BÀN GIAO'!#REF! -> #REF! | E24: ='BIÊN BẢN BÀN GIAO'!#REF! -> #REF!
D25: ='BIÊN BẢN BÀN GIAO'!#REF! -> #REF! | E25: ='BIÊN BẢN BÀN GIAO'!#REF! -> #REF!
D26: ='BIÊN BẢN BÀN GIAO'!D15 -> 01ERC3001-001 | E26: ='BIÊN BẢN BÀN GIAO'!E15 -> ERC3001
D27: ='BIÊN BẢN BÀN GIAO'!#REF! -> #REF! | E27: ='BIÊN BẢN BÀN GIAO'!#REF! -> #REF!
D28: ='BIÊN BẢN BÀN GIAO'!D16 -> 01ERC3001-004 | E28: ='BIÊN BẢN BÀN GIAO'!E16 -> ERC3001
D29: ='BIÊN BẢN BÀN GIAO'!#REF! -> #REF! | E29: ='BIÊN BẢN BÀN GIAO'!#REF! -> #REF! | L29: =D16 -> #REF! | M29: =E16 -> #REF! | N29: 2
D30: ='BIÊN BẢN BÀN GIAO'!#REF! -> #REF! | E30: ='BIÊN BẢN BÀN GIAO'!#REF! -> #REF!
D31: ='BIÊN BẢN BÀN GIAO'!#REF! -> #REF! | E31: ='BIÊN BẢN BÀN GIAO'!#REF! -> #REF! | L31: =D34 -> #REF! | M31: =E34 -> #REF! | N31: 2
D32: ='BIÊN BẢN BÀN GIAO'!#REF! -> #REF! | E32: ='BIÊN BẢN BÀN GIAO'!#REF! -> #REF! | L32: =D35 -> #REF! | M32: =E35 -> #REF!
D33: ='BIÊN BẢN BÀN GIAO'!#REF! -> #REF! | E33: ='BIÊN BẢN BÀN GIAO'!#REF! -> #REF!
D34: ='BIÊN BẢN BÀN GIAO'!#REF! -> #REF! | E34: ='BIÊN BẢN BÀN GIAO'!#REF! -> #REF! | L34: =D72 -> #REF! | M34: =E72 -> #REF! | N34: 1
D35: ='BIÊN BẢN BÀN GIAO'!#REF! -> #REF! | E35: ='BIÊN BẢN BÀN GIAO'!#REF! -> #REF! | L35: =D73 -> #REF! | M35: =E73 -> #REF!
D36: ='BIÊN BẢN BÀN GIAO'!#REF! -> #REF! | E36: ='BIÊN BẢN BÀN GIAO'!#REF! -> #REF! | L36: =D74 -> #REF! | M36: =E74 -> #REF! | N36: 1
D37: ='BIÊN BẢN BÀN GIAO'!#REF! -> #REF! | E37: ='BIÊN BẢN BÀN GIAO'!#REF! -> #REF! | L37: =D75 -> 01ERC3001-003 | M37: =E75 -> ERC3001
D38: ='BIÊN BẢN BÀN GIAO'!#REF! -> #REF! | E38: ='BIÊN BẢN BÀN GIAO'!#REF! -> #REF!
D39: ='BIÊN BẢN BÀN GIAO'!#REF! -> #REF! | E39: ='BIÊN BẢN BÀN GIAO'!#REF! -> #REF!
D41: ='BIÊN BẢN BÀN GIAO'!#REF! -> #REF! | E41: ='BIÊN BẢN BÀN GIAO'!#REF! -> #REF!
D45: ='BIÊN BẢN BÀN GIAO'!#REF! -> #REF! | E45: ='BIÊN BẢN BÀN GIAO'!#REF! -> #REF! | F45: 2
D46: ='BIÊN BẢN BÀN GIAO'!#REF! -> #REF! | E46: ='BIÊN BẢN BÀN GIAO'!#REF! -> #REF!
...
